{"uuid": "ca909f7a-0df8-47d4-94a3-39b7a4c5f602", "children": ["7bf12bf7-6c18-4bd0-bdb9-03dabf9b0946"], "befores": [{"name": "browser", "status": "broken", "statusDetails": {"message": "selenium.common.exceptions.SessionNotCreatedException: Message: create container: Error response from daemon: No such image: selenoid/firefox:108.0\n\n", "trace": "  File \"/Users/user/opt/anaconda3/lib/python3.9/site-packages/pluggy/_callers.py\", line 39, in _multicall\n    res = hook_impl.function(*args)\n  File \"/Users/user/opt/anaconda3/lib/python3.9/site-packages/_pytest/fixtures.py\", line 1128, in pytest_fixture_setup\n    result = call_fixture_func(fixturefunc, request, kwargs)\n  File \"/Users/user/opt/anaconda3/lib/python3.9/site-packages/_pytest/fixtures.py\", line 907, in call_fixture_func\n    fixture_result = fixturefunc(**kwargs)\n  File \"/Users/user/Documents/auto-web-qa/homework12/conftest.py\", line 109, in browser\n    driver = webdriver.Remote(\n  File \"/Users/user/opt/anaconda3/lib/python3.9/site-packages/selenium/webdriver/remote/webdriver.py\", line 288, in __init__\n    self.start_session(capabilities, browser_profile)\n  File \"/Users/user/opt/anaconda3/lib/python3.9/site-packages/selenium/webdriver/remote/webdriver.py\", line 381, in start_session\n    response = self.execute(Command.NEW_SESSION, parameters)\n  File \"/Users/user/opt/anaconda3/lib/python3.9/site-packages/selenium/webdriver/remote/webdriver.py\", line 444, in execute\n    self.error_handler.check_response(response)\n  File \"/Users/user/opt/anaconda3/lib/python3.9/site-packages/selenium/webdriver/remote/errorhandler.py\", line 249, in check_response\n    raise exception_class(message, screen, stacktrace)\n"}, "start": 1677581440563, "stop": 1677581440570}], "start": 1677581440563, "stop": 1677581440606}