{"uuid": "df48b4aa-d580-4a72-a1a0-92929e7ce971", "children": ["53d94077-64d8-4826-bbb0-80c47aa2dbfa"], "befores": [{"name": "browser", "status": "broken", "statusDetails": {"message": "selenium.common.exceptions.SessionNotCreatedException: Message: create container: Error response from daemon: No such image: selenoid/firefox:108.0\n\n", "trace": "  File \"/Users/user/opt/anaconda3/lib/python3.9/site-packages/pluggy/_callers.py\", line 39, in _multicall\n    res = hook_impl.function(*args)\n  File \"/Users/user/opt/anaconda3/lib/python3.9/site-packages/_pytest/fixtures.py\", line 1128, in pytest_fixture_setup\n    result = call_fixture_func(fixturefunc, request, kwargs)\n  File \"/Users/user/opt/anaconda3/lib/python3.9/site-packages/_pytest/fixtures.py\", line 907, in call_fixture_func\n    fixture_result = fixturefunc(**kwargs)\n  File \"/Users/user/Documents/auto-web-qa/homework12/conftest.py\", line 109, in browser\n    driver = webdriver.Remote(\n  File \"/Users/user/opt/anaconda3/lib/python3.9/site-packages/selenium/webdriver/remote/webdriver.py\", line 288, in __init__\n    self.start_session(capabilities, browser_profile)\n  File \"/Users/user/opt/anaconda3/lib/python3.9/site-packages/selenium/webdriver/remote/webdriver.py\", line 381, in start_session\n    response = self.execute(Command.NEW_SESSION, parameters)\n  File \"/Users/user/opt/anaconda3/lib/python3.9/site-packages/selenium/webdriver/remote/webdriver.py\", line 444, in execute\n    self.error_handler.check_response(response)\n  File \"/Users/user/opt/anaconda3/lib/python3.9/site-packages/selenium/webdriver/remote/errorhandler.py\", line 249, in check_response\n    raise exception_class(message, screen, stacktrace)\n"}, "start": 1677581440455, "stop": 1677581440464}], "start": 1677581440455, "stop": 1677581440490}