{"uuid": "d61ccae1-bcad-44a5-927e-658e9e81b2af", "children": ["490d38e1-fdfa-4959-96cd-e31ae9dcfeb9"], "befores": [{"name": "browser", "status": "broken", "statusDetails": {"message": "urllib3.exceptions.MaxRetryError: HTTPConnectionPool(host='192.168.0.102', port=4444): Max retries exceeded with url: /wd/hub/session (Caused by NewConnectionError('<urllib3.connection.HTTPConnection object at 0x7fd8b10fc8e0>: Failed to establish a new connection: [Errno 61] Connection refused'))\n", "trace": "  File \"/Users/user/opt/anaconda3/lib/python3.9/site-packages/pluggy/_callers.py\", line 39, in _multicall\n    res = hook_impl.function(*args)\n  File \"/Users/user/opt/anaconda3/lib/python3.9/site-packages/_pytest/fixtures.py\", line 1128, in pytest_fixture_setup\n    result = call_fixture_func(fixturefunc, request, kwargs)\n  File \"/Users/user/opt/anaconda3/lib/python3.9/site-packages/_pytest/fixtures.py\", line 907, in call_fixture_func\n    fixture_result = fixturefunc(**kwargs)\n  File \"/Users/user/Documents/auto-web-qa/homework12/conftest.py\", line 109, in browser\n    driver = webdriver.Remote(\n  File \"/Users/user/opt/anaconda3/lib/python3.9/site-packages/selenium/webdriver/remote/webdriver.py\", line 288, in __init__\n    self.start_session(capabilities, browser_profile)\n  File \"/Users/user/opt/anaconda3/lib/python3.9/site-packages/selenium/webdriver/remote/webdriver.py\", line 381, in start_session\n    response = self.execute(Command.NEW_SESSION, parameters)\n  File \"/Users/user/opt/anaconda3/lib/python3.9/site-packages/selenium/webdriver/remote/webdriver.py\", line 442, in execute\n    response = self.command_executor.execute(driver_command, params)\n  File \"/Users/user/opt/anaconda3/lib/python3.9/site-packages/selenium/webdriver/remote/remote_connection.py\", line 294, in execute\n    return self._request(command_info[0], url, body=data)\n  File \"/Users/user/opt/anaconda3/lib/python3.9/site-packages/selenium/webdriver/remote/remote_connection.py\", line 316, in _request\n    response = self._conn.request(method, url, body=body, headers=headers)\n  File \"/Users/user/opt/anaconda3/lib/python3.9/site-packages/urllib3/request.py\", line 78, in request\n    return self.request_encode_body(\n  File \"/Users/user/opt/anaconda3/lib/python3.9/site-packages/urllib3/request.py\", line 170, in request_encode_body\n    return self.urlopen(method, url, **extra_kw)\n  File \"/Users/user/opt/anaconda3/lib/python3.9/site-packages/urllib3/poolmanager.py\", line 376, in urlopen\n    response = conn.urlopen(method, u.request_uri, **kw)\n  File \"/Users/user/opt/anaconda3/lib/python3.9/site-packages/urllib3/connectionpool.py\", line 813, in urlopen\n    return self.urlopen(\n  File \"/Users/user/opt/anaconda3/lib/python3.9/site-packages/urllib3/connectionpool.py\", line 813, in urlopen\n    return self.urlopen(\n  File \"/Users/user/opt/anaconda3/lib/python3.9/site-packages/urllib3/connectionpool.py\", line 813, in urlopen\n    return self.urlopen(\n  File \"/Users/user/opt/anaconda3/lib/python3.9/site-packages/urllib3/connectionpool.py\", line 785, in urlopen\n    retries = retries.increment(\n  File \"/Users/user/opt/anaconda3/lib/python3.9/site-packages/urllib3/util/retry.py\", line 592, in increment\n    raise MaxRetryError(_pool, url, error or ResponseError(cause))\n"}, "start": 1677358188782, "stop": 1677358192795}], "start": 1677358188782, "stop": 1677358192949}